<mujoco model="obj">
  <default>
    <default class="obj/visual">
      <geom group="2" type="mesh" contype="0" conaffinity="0"/>
    </default>
    <default class="obj/collision">
      <geom group="3" type="mesh"/>
    </default>
  </default>
  <asset>
    <texture type="2d" name="img0" file="objects/00/img0.png"/>
    <material name="material_0" texture="img0" specular="0.0" shininess="0.0"/>
    <mesh file="objects/00/00.obj"/>
  </asset>
  <worldbody>
    <body name="obj" pos="-1.5 0 1">
      <joint name="obj_jnt" type="ball"/>
      <geom material="material_0" mesh="00" class="obj/visual"/>
      <geom mesh="00" class="obj/collision" mass="0.5"/>
    </body>
  </worldbody>
</mujoco>