<mujoco model="floor">
  <compiler autolimits="true" boundmass="1.0000000000000001e-05" boundinertia="9.9999999999999994e-12" coordinate="local" angle="radian" eulerseq="xyz"/>
  <option timestep="0.002" impratio="10" integrator="implicit" cone="elliptic" noslip_iterations="5" noslip_tolerance="0"/>
  <visual>
    <headlight ambient="0.40000000000000002 0.40000000000000002 0.40000000000000002" diffuse="0.80000000000000004 0.80000000000000004 0.80000000000000004" specular="0.10000000000000001 0.10000000000000001 0.10000000000000001"/>
    <map znear="0.01"/>
    <scale forcewidth="0.01" contactwidth="0.059999999999999998" contactheight="0.01" jointwidth="0.01" framelength="0.29999999999999999" framewidth="0.01"/>
  </visual>
  <default>
    <default class="/"/>
    <default class="panda/">
      <default class="panda/panda">
        <material specular="0.5" shininess="0.25"/>
        <joint axis="0 0 1" range="-2.8973 2.8973" armature="0.10000000000000001" damping="1"/>
        <site group="4" rgba="0.5 0.5 0.5 0.29999999999999999" size="0.001"/>
        <default class="panda/finger">
          <joint type="slide" axis="0 1 0" range="0 0.040000000000000001"/>
        </default>
        <default class="panda/visual">
          <geom type="mesh" contype="0" conaffinity="0" group="2"/>
        </default>
        <default class="panda/collision">
          <geom type="mesh" group="3"/>
        </default>
      </default>
    </default>
    <default class="panda/whip/">
      <default class="panda/whip/whip">
        <default class="panda/whip/X">
          <joint type="hinge" pos="0 0 0" axis="1 0 0" stiffness="0.24199999999999999" springref="0" damping="0.091999999999999998"/>
        </default>
        <default class="panda/whip/Y">
          <joint type="hinge" pos="0 0 0" axis="0 1 0" stiffness="0.24199999999999999" springref="0" damping="0.091999999999999998"/>
        </default>
        <default class="panda/whip/sphere">
          <geom type="sphere" size="0.0060000000000000001" material="panda/whip/white" mass="0.012" pos="0 0 0.035999999999999997"/>
        </default>
        <default class="panda/whip/cylinder">
          <geom type="cylinder" size="0.0060000000000000001" material="panda/whip/white" mass="0" fromto="0 0 0 0 0 0.035999999999999997"/>
        </default>
      </default>
    </default>
    <default class="obj/">
      <default class="obj/visual">
        <geom type="mesh" contype="0" conaffinity="0" group="2"/>
      </default>
      <default class="obj/collision">
        <geom type="mesh" group="3"/>
      </default>
    </default>
  </default>
  <asset>
    <texture name="groundplane" type="2d" builtin="checker" rgb1="0.20000000000000001 0.29999999999999999 0.40000000000000002" rgb2="0.10000000000000001 0.20000000000000001 0.29999999999999999" mark="edge" markrgb="0.80000000000000004 0.80000000000000004 0.80000000000000004" width="200" height="200"/>
    <material name="groundplane" class="/" texture="groundplane" texrepeat="2 2" texuniform="true" reflectance="0.20000000000000001"/>
    <material name="panda/white" class="panda/panda" rgba="1 1 1 1"/>
    <material name="panda/off_white" class="panda/panda" rgba="0.90196100000000001 0.92156899999999997 0.92941200000000002 1"/>
    <material name="panda/dark_grey" class="panda/panda" rgba="0.25 0.25 0.25 1"/>
    <material name="panda/green" class="panda/panda" rgba="0 1 0 1"/>
    <material name="panda/light_blue" class="panda/panda" rgba="0.039216000000000001 0.54117599999999999 0.78039199999999997 1"/>
    <mesh name="panda/link0_c" class="panda/" file="link0-3f633d19409870795516c6de40b4c7922f53c43d.stl"/>
    <mesh name="panda/link1_c" class="panda/" file="link1-53f934209b6019b996b6d9c714d0a9cf102f7fb2.stl"/>
    <mesh name="panda/link2_c" class="panda/" file="link2-8500c695b73e8ceeaa520c02db5684f02793b80f.stl"/>
    <mesh name="panda/link3_c" class="panda/" file="link3-0af960563df21dd3a3b0afac6e34f62bf10c71c4.stl"/>
    <mesh name="panda/link4_c" class="panda/" file="link4-97c9a53ee35f3939b3438a38005e78fd4c9f23cb.stl"/>
    <mesh name="panda/link5_c0" class="panda/" file="link5_collision_0-f402b8885893e833c27f7eca01b669b81476a48f.obj"/>
    <mesh name="panda/link5_c1" class="panda/" file="link5_collision_1-3735bde5d4211e2d565b9cc20b919f55e697be05.obj"/>
    <mesh name="panda/link5_c2" class="panda/" file="link5_collision_2-585e84d1d7e381827b73c7ecd50f2010775235c9.obj"/>
    <mesh name="panda/link6_c" class="panda/" file="link6-e9fa3ad660cf2a9b04e0ec55e8d56abf5891d531.stl"/>
    <mesh name="panda/link7_c" class="panda/" file="link7-5dcc7199c8e231447ebda37651ead64ebe3cf6ec.stl"/>
    <mesh name="panda/link0_0" class="panda/" file="link0_0-b7cf6e228cebc1309b79491310541fe8a60e2d62.obj"/>
    <mesh name="panda/link0_1" class="panda/" file="link0_1-5ecc0c585f0d6a4207ba87f6aeed2df5632b2ebe.obj"/>
    <mesh name="panda/link0_2" class="panda/" file="link0_2-88529048e478fb7cca6eeeaaa0405b00ca337c0a.obj"/>
    <mesh name="panda/link0_3" class="panda/" file="link0_3-75c03dfe4002c399dfeaea609db33c25ae42f82f.obj"/>
    <mesh name="panda/link0_4" class="panda/" file="link0_4-6917a10a52309fc722169515f143ac9bd6a2b084.obj"/>
    <mesh name="panda/link0_5" class="panda/" file="link0_5-8d54ecd0c38e0b412ac31ef46675fdca7e0e4717.obj"/>
    <mesh name="panda/link0_7" class="panda/" file="link0_7-79cbcc01643937964f9e547e9b3d225888aa50c7.obj"/>
    <mesh name="panda/link0_8" class="panda/" file="link0_8-4c89da97ea30fff7777d1a961c922a48425291ef.obj"/>
    <mesh name="panda/link0_9" class="panda/" file="link0_9-776b30016c2bb8f206d560786910bfccb809926d.obj"/>
    <mesh name="panda/link0_10" class="panda/" file="link0_10-d7b529ebc6940c0415ad91e938b0c39f05853d07.obj"/>
    <mesh name="panda/link0_11" class="panda/" file="link0_11-46418d08940dd95e72b8290253d6bfb37aa3ba10.obj"/>
    <mesh name="panda/link1" class="panda/" file="link1-ed231c089447a0928504d8a0b6d31c196f6f4b28.obj"/>
    <mesh name="panda/link2" class="panda/" file="link2-21fdd1eb16bc9d11a5349b39cc21c9ecafff6cb2.obj"/>
    <mesh name="panda/link3_0" class="panda/" file="link3_0-644740d89be54fee424dac34a096ed07f0c0be9a.obj"/>
    <mesh name="panda/link3_1" class="panda/" file="link3_1-aa5980b7ffb0ff37d6f81bf5d03cca87b4182c72.obj"/>
    <mesh name="panda/link3_2" class="panda/" file="link3_2-41efc81a33bb7585a8676c163e2d66ac5cc1fbb5.obj"/>
    <mesh name="panda/link3_3" class="panda/" file="link3_3-c433c61f6a518e2810fa405a084aa55ae95bc09c.obj"/>
    <mesh name="panda/link4_0" class="panda/" file="link4_0-70b359cb835f79b58037732ffb174c30589ca379.obj"/>
    <mesh name="panda/link4_1" class="panda/" file="link4_1-8a206f8e5eee869db6b4d9e77db083f6edbc5e6b.obj"/>
    <mesh name="panda/link4_2" class="panda/" file="link4_2-5c5b38db50c3864953a5ee4766d35f5fae84e0dc.obj"/>
    <mesh name="panda/link4_3" class="panda/" file="link4_3-46cdfe6cf343836b30218551cd40c45197cd3f7d.obj"/>
    <mesh name="panda/link5_0" class="panda/" file="link5_0-c9c057e806e8a7919fb33f70114229b6d3c40dcd.obj"/>
    <mesh name="panda/link5_1" class="panda/" file="link5_1-f07ba3f01e7be86042be33cef54249a02bd73749.obj"/>
    <mesh name="panda/link5_2" class="panda/" file="link5_2-fc227a4bf91b7bc23a55448c810557f391f1d5e3.obj"/>
    <mesh name="panda/link6_0" class="panda/" file="link6_0-6836f8b697cf67e536dc9bbd5fa9250c58c12ca7.obj"/>
    <mesh name="panda/link6_1" class="panda/" file="link6_1-d0da79111a0c81081fcdfa01fb58586c92d8322d.obj"/>
    <mesh name="panda/link6_2" class="panda/" file="link6_2-d6b659cb277c78c300d62cdb6449eaaa8814b5d2.obj"/>
    <mesh name="panda/link6_3" class="panda/" file="link6_3-ba09733138cd64d0a7366ffe1385267da3597481.obj"/>
    <mesh name="panda/link6_4" class="panda/" file="link6_4-32e7cb101a33786176152037acd0a8872e7d5ad5.obj"/>
    <mesh name="panda/link6_5" class="panda/" file="link6_5-38d0c1ecd191ee8d914ba6b7a6afa271432c665f.obj"/>
    <mesh name="panda/link6_6" class="panda/" file="link6_6-5ed9d943e4d2c63735b56d3e3635a3a07c6470db.obj"/>
    <mesh name="panda/link6_7" class="panda/" file="link6_7-106080e92cb497bc3906f4e5ee2f49fd62ea7f89.obj"/>
    <mesh name="panda/link6_8" class="panda/" file="link6_8-bbfe67149c4cfd9d81968a91844069d474f53f2d.obj"/>
    <mesh name="panda/link6_9" class="panda/" file="link6_9-09876ce72bf2f306c3ac7005f461a2d88f78dccd.obj"/>
    <mesh name="panda/link6_10" class="panda/" file="link6_10-b0430678bf45d2dcb5a064b8a19f1f93945864fb.obj"/>
    <mesh name="panda/link6_11" class="panda/" file="link6_11-dbcbe820a516782674773335ffc26931de719df1.obj"/>
    <mesh name="panda/link6_12" class="panda/" file="link6_12-7f56f8ec4561cb5b724ff00e00d6f0efe8bf7123.obj"/>
    <mesh name="panda/link6_13" class="panda/" file="link6_13-a0d4d39ca68ff2ec5a17977ecc13dc02b5b4fdd2.obj"/>
    <mesh name="panda/link6_14" class="panda/" file="link6_14-fde4741db758169025860d9d06157c80aab9f9c0.obj"/>
    <mesh name="panda/link6_15" class="panda/" file="link6_15-5e7addd48c4088cfeb5280ef77bc69e4cdb45939.obj"/>
    <mesh name="panda/link6_16" class="panda/" file="link6_16-d583372e8c9632ad1aa003ef6c5ac09effbf2102.obj"/>
    <mesh name="panda/link7_0" class="panda/" file="link7_0-2e4ca001c5c670d1e7b84e342df95cc1b01ee137.obj"/>
    <mesh name="panda/link7_1" class="panda/" file="link7_1-3dfe858021e5f7d422c2f51e5663f07272b758fc.obj"/>
    <mesh name="panda/link7_2" class="panda/" file="link7_2-2643e68c73e2988b9f66992bdd9ea846cae1e128.obj"/>
    <mesh name="panda/link7_3" class="panda/" file="link7_3-9eff475605fd7c4d72ff0031ee375b7bab95920b.obj"/>
    <mesh name="panda/link7_4" class="panda/" file="link7_4-6ea88c0c0f5a79079aa03008291a9df01ea43ed5.obj"/>
    <mesh name="panda/link7_5" class="panda/" file="link7_5-916ac62d00e858d819cb553fe73db314185cdd47.obj"/>
    <mesh name="panda/link7_6" class="panda/" file="link7_6-9d637adbf9ceabb0d5f85515c03d065c54fde3dc.obj"/>
    <mesh name="panda/link7_7" class="panda/" file="link7_7-652eee34bbafccbee18e5c1c8f96823fcaaf242d.obj"/>
    <material name="panda/whip/white" class="panda/whip/whip" rgba="1 1 1 1"/>
    <texture name="obj/img7" type="2d" file="img7-62b89a4c9da65f21c4c4707881422721fa35a9af.png"/>
    <material name="obj/material_0.007" class="obj/" texture="obj/img7" specular="0" shininess="0"/>
    <mesh name="obj/07" class="obj/" file="07-157c4cfb358094b1e207096640b3e7f56aba3958.obj"/>
  </asset>
  <worldbody>
    <geom name="groundplane" class="/" type="plane" size="8 8 0.25" material="groundplane"/>
    <camera name="top_camera" class="/" fovy="10.058147163570894" pos="0 0 100" quat="1 0 0 0"/>
    <body name="panda/">
      <body name="panda/link0" childclass="panda/panda">
        <inertial pos="-0.041017999999999999 -0.00013999999999999999 0.049973999999999998" mass="0.62976900000000002" fullinertia="0.00315 0.0038800000000000002 0.0042849999999999997 8.2903999999999996e-07 0.00014999999999999999 8.2299000000000006e-06"/>
        <geom name="panda//unnamed_geom_0" class="panda/visual" material="panda/off_white" mesh="panda/link0_0"/>
        <geom name="panda//unnamed_geom_1" class="panda/visual" material="panda/dark_grey" mesh="panda/link0_1"/>
        <geom name="panda//unnamed_geom_2" class="panda/visual" material="panda/off_white" mesh="panda/link0_2"/>
        <geom name="panda//unnamed_geom_3" class="panda/visual" material="panda/dark_grey" mesh="panda/link0_3"/>
        <geom name="panda//unnamed_geom_4" class="panda/visual" material="panda/off_white" mesh="panda/link0_4"/>
        <geom name="panda//unnamed_geom_5" class="panda/visual" material="panda/dark_grey" mesh="panda/link0_5"/>
        <geom name="panda//unnamed_geom_6" class="panda/visual" material="panda/white" mesh="panda/link0_7"/>
        <geom name="panda//unnamed_geom_7" class="panda/visual" material="panda/white" mesh="panda/link0_8"/>
        <geom name="panda//unnamed_geom_8" class="panda/visual" material="panda/dark_grey" mesh="panda/link0_9"/>
        <geom name="panda//unnamed_geom_9" class="panda/visual" material="panda/off_white" mesh="panda/link0_10"/>
        <geom name="panda//unnamed_geom_10" class="panda/visual" material="panda/white" mesh="panda/link0_11"/>
        <geom name="panda//unnamed_geom_11" class="panda/collision" mesh="panda/link0_c"/>
        <body name="panda/link1" pos="0 0 0.33300000000000002">
          <inertial pos="0.003875 0.002081 -0.047620000000000003" mass="4.9706840000000003" fullinertia="0.70337000000000005 0.70660999999999996 0.0091170000000000001 -0.00013899999999999999 0.0067720000000000002 0.019168999999999999"/>
          <joint name="panda/joint1"/>
          <geom name="panda//unnamed_geom_12" class="panda/visual" material="panda/white" mesh="panda/link1"/>
          <geom name="panda//unnamed_geom_13" class="panda/collision" mesh="panda/link1_c"/>
          <body name="panda/link2" quat="1 -1 0 0">
            <inertial pos="-0.0031410000000000001 -0.028719999999999999 0.0034949999999999998" mass="0.646926" fullinertia="0.0079620000000000003 0.02811 0.025995000000000001 -0.0039249999999999997 0.010253999999999999 0.00070399999999999998"/>
            <joint name="panda/joint2" range="-1.7627999999999999 1.7627999999999999"/>
            <geom name="panda//unnamed_geom_14" class="panda/visual" material="panda/white" mesh="panda/link2"/>
            <geom name="panda//unnamed_geom_15" class="panda/collision" mesh="panda/link2_c"/>
            <body name="panda/link3" pos="0 -0.316 0" quat="1 1 0 0">
              <joint name="panda/joint3"/>
              <inertial pos="0.027518000000000001 0.039252000000000002 -0.066502000000000006" mass="3.2286039999999998" fullinertia="0.037241999999999997 0.036155 0.010829999999999999 -0.0047609999999999996 -0.011396 -0.012805"/>
              <geom name="panda//unnamed_geom_16" class="panda/visual" material="panda/white" mesh="panda/link3_0"/>
              <geom name="panda//unnamed_geom_17" class="panda/visual" material="panda/white" mesh="panda/link3_1"/>
              <geom name="panda//unnamed_geom_18" class="panda/visual" material="panda/white" mesh="panda/link3_2"/>
              <geom name="panda//unnamed_geom_19" class="panda/visual" material="panda/dark_grey" mesh="panda/link3_3"/>
              <geom name="panda//unnamed_geom_20" class="panda/collision" mesh="panda/link3_c"/>
              <body name="panda/link4" pos="0.082500000000000004 0 0" quat="1 1 0 0">
                <inertial pos="-0.053170000000000002 0.104419 0.027453999999999999" mass="3.5878950000000001" fullinertia="0.025853000000000001 0.019552 0.028323000000000001 0.007796 -0.0013320000000000001 0.0086409999999999994"/>
                <joint name="panda/joint4" range="-3.0718000000000001 -0.069800000000000001"/>
                <geom name="panda//unnamed_geom_21" class="panda/visual" material="panda/white" mesh="panda/link4_0"/>
                <geom name="panda//unnamed_geom_22" class="panda/visual" material="panda/white" mesh="panda/link4_1"/>
                <geom name="panda//unnamed_geom_23" class="panda/visual" material="panda/dark_grey" mesh="panda/link4_2"/>
                <geom name="panda//unnamed_geom_24" class="panda/visual" material="panda/white" mesh="panda/link4_3"/>
                <geom name="panda//unnamed_geom_25" class="panda/collision" mesh="panda/link4_c"/>
                <body name="panda/link5" pos="-0.082500000000000004 0.38400000000000001 0" quat="1 -1 0 0">
                  <inertial pos="-0.011953 0.041064999999999997 -0.038436999999999999" mass="1.225946" fullinertia="0.035548999999999997 0.029474 0.0086269999999999993 -0.002117 -0.0040369999999999998 0.00022900000000000001"/>
                  <joint name="panda/joint5"/>
                  <geom name="panda//unnamed_geom_26" class="panda/visual" material="panda/dark_grey" mesh="panda/link5_0"/>
                  <geom name="panda//unnamed_geom_27" class="panda/visual" material="panda/white" mesh="panda/link5_1"/>
                  <geom name="panda//unnamed_geom_28" class="panda/visual" material="panda/white" mesh="panda/link5_2"/>
                  <geom name="panda//unnamed_geom_29" class="panda/collision" mesh="panda/link5_c0"/>
                  <geom name="panda//unnamed_geom_30" class="panda/collision" mesh="panda/link5_c1"/>
                  <geom name="panda//unnamed_geom_31" class="panda/collision" mesh="panda/link5_c2"/>
                  <body name="panda/link6" quat="1 1 0 0">
                    <inertial pos="0.060149000000000001 -0.014116999999999999 -0.010517" mass="1.666555" fullinertia="0.001964 0.0043540000000000002 0.0054330000000000003 0.00010900000000000001 -0.001158 0.00034099999999999999"/>
                    <joint name="panda/joint6" range="-0.017500000000000002 3.7524999999999999"/>
                    <geom name="panda//unnamed_geom_32" class="panda/visual" material="panda/off_white" mesh="panda/link6_0"/>
                    <geom name="panda//unnamed_geom_33" class="panda/visual" material="panda/white" mesh="panda/link6_1"/>
                    <geom name="panda//unnamed_geom_34" class="panda/visual" material="panda/dark_grey" mesh="panda/link6_2"/>
                    <geom name="panda//unnamed_geom_35" class="panda/visual" material="panda/white" mesh="panda/link6_3"/>
                    <geom name="panda//unnamed_geom_36" class="panda/visual" material="panda/white" mesh="panda/link6_4"/>
                    <geom name="panda//unnamed_geom_37" class="panda/visual" material="panda/white" mesh="panda/link6_5"/>
                    <geom name="panda//unnamed_geom_38" class="panda/visual" material="panda/white" mesh="panda/link6_6"/>
                    <geom name="panda//unnamed_geom_39" class="panda/visual" material="panda/light_blue" mesh="panda/link6_7"/>
                    <geom name="panda//unnamed_geom_40" class="panda/visual" material="panda/light_blue" mesh="panda/link6_8"/>
                    <geom name="panda//unnamed_geom_41" class="panda/visual" material="panda/dark_grey" mesh="panda/link6_9"/>
                    <geom name="panda//unnamed_geom_42" class="panda/visual" material="panda/dark_grey" mesh="panda/link6_10"/>
                    <geom name="panda//unnamed_geom_43" class="panda/visual" material="panda/white" mesh="panda/link6_11"/>
                    <geom name="panda//unnamed_geom_44" class="panda/visual" material="panda/green" mesh="panda/link6_12"/>
                    <geom name="panda//unnamed_geom_45" class="panda/visual" material="panda/white" mesh="panda/link6_13"/>
                    <geom name="panda//unnamed_geom_46" class="panda/visual" material="panda/dark_grey" mesh="panda/link6_14"/>
                    <geom name="panda//unnamed_geom_47" class="panda/visual" material="panda/dark_grey" mesh="panda/link6_15"/>
                    <geom name="panda//unnamed_geom_48" class="panda/visual" material="panda/white" mesh="panda/link6_16"/>
                    <geom name="panda//unnamed_geom_49" class="panda/collision" mesh="panda/link6_c"/>
                    <body name="panda/link7" pos="0.087999999999999995 0 0" quat="1 1 0 0">
                      <inertial pos="0.010517 -0.0042519999999999997 0.061596999999999999" mass="0.73552200000000001" fullinertia="0.012515999999999999 0.010026999999999999 0.0048149999999999998 -0.000428 -0.001196 -0.00074100000000000001"/>
                      <joint name="panda/joint7"/>
                      <geom name="panda//unnamed_geom_50" class="panda/visual" material="panda/white" mesh="panda/link7_0"/>
                      <geom name="panda//unnamed_geom_51" class="panda/visual" material="panda/dark_grey" mesh="panda/link7_1"/>
                      <geom name="panda//unnamed_geom_52" class="panda/visual" material="panda/dark_grey" mesh="panda/link7_2"/>
                      <geom name="panda//unnamed_geom_53" class="panda/visual" material="panda/dark_grey" mesh="panda/link7_3"/>
                      <geom name="panda//unnamed_geom_54" class="panda/visual" material="panda/dark_grey" mesh="panda/link7_4"/>
                      <geom name="panda//unnamed_geom_55" class="panda/visual" material="panda/dark_grey" mesh="panda/link7_5"/>
                      <geom name="panda//unnamed_geom_56" class="panda/visual" material="panda/dark_grey" mesh="panda/link7_6"/>
                      <geom name="panda//unnamed_geom_57" class="panda/visual" material="panda/white" mesh="panda/link7_7"/>
                      <geom name="panda//unnamed_geom_58" class="panda/collision" mesh="panda/link7_c"/>
                      <site name="panda/mount_site" size="0.0050000000000000001" pos="0 0 0.107"/>
                      <body pos="0 0 0.107" name="panda/whip/">
                        <body name="panda/whip/whip" childclass="panda/whip/whip">
                          <geom name="panda/whip//unnamed_geom_0" type="sphere" size="0.044999999999999998" material="panda/whip/white"/>
                          <body name="panda/whip/N00" pos="0 0 0.044999999999999998">
                            <joint name="panda/whip//unnamed_joint_0" class="panda/whip/X"/>
                            <joint name="panda/whip//unnamed_joint_1" class="panda/whip/Y"/>
                            <geom name="panda/whip//unnamed_geom_1" class="panda/whip/cylinder"/>
                            <geom name="panda/whip//unnamed_geom_2" class="panda/whip/sphere"/>
                            <body name="panda/whip/N01" pos="0 0 0.035999999999999997">
                              <joint name="panda/whip//unnamed_joint_2" class="panda/whip/X"/>
                              <joint name="panda/whip//unnamed_joint_3" class="panda/whip/Y"/>
                              <geom name="panda/whip//unnamed_geom_3" class="panda/whip/cylinder"/>
                              <geom name="panda/whip//unnamed_geom_4" class="panda/whip/sphere"/>
                              <body name="panda/whip/N02" pos="0 0 0.035999999999999997">
                                <joint name="panda/whip//unnamed_joint_4" class="panda/whip/X"/>
                                <joint name="panda/whip//unnamed_joint_5" class="panda/whip/Y"/>
                                <geom name="panda/whip//unnamed_geom_5" class="panda/whip/cylinder"/>
                                <geom name="panda/whip//unnamed_geom_6" class="panda/whip/sphere"/>
                                <body name="panda/whip/N03" pos="0 0 0.035999999999999997">
                                  <joint name="panda/whip//unnamed_joint_6" class="panda/whip/X"/>
                                  <joint name="panda/whip//unnamed_joint_7" class="panda/whip/Y"/>
                                  <geom name="panda/whip//unnamed_geom_7" class="panda/whip/cylinder"/>
                                  <geom name="panda/whip//unnamed_geom_8" class="panda/whip/sphere"/>
                                  <body name="panda/whip/N04" pos="0 0 0.035999999999999997">
                                    <joint name="panda/whip//unnamed_joint_8" class="panda/whip/X"/>
                                    <joint name="panda/whip//unnamed_joint_9" class="panda/whip/Y"/>
                                    <geom name="panda/whip//unnamed_geom_9" class="panda/whip/cylinder"/>
                                    <geom name="panda/whip//unnamed_geom_10" class="panda/whip/sphere"/>
                                    <body name="panda/whip/N05" pos="0 0 0.035999999999999997">
                                      <joint name="panda/whip//unnamed_joint_10" class="panda/whip/X"/>
                                      <joint name="panda/whip//unnamed_joint_11" class="panda/whip/Y"/>
                                      <geom name="panda/whip//unnamed_geom_11" class="panda/whip/cylinder"/>
                                      <geom name="panda/whip//unnamed_geom_12" class="panda/whip/sphere"/>
                                      <body name="panda/whip/N06" pos="0 0 0.035999999999999997">
                                        <joint name="panda/whip//unnamed_joint_12" class="panda/whip/X"/>
                                        <joint name="panda/whip//unnamed_joint_13" class="panda/whip/Y"/>
                                        <geom name="panda/whip//unnamed_geom_13" class="panda/whip/cylinder"/>
                                        <geom name="panda/whip//unnamed_geom_14" class="panda/whip/sphere"/>
                                        <body name="panda/whip/N07" pos="0 0 0.035999999999999997">
                                          <joint name="panda/whip//unnamed_joint_14" class="panda/whip/X"/>
                                          <joint name="panda/whip//unnamed_joint_15" class="panda/whip/Y"/>
                                          <geom name="panda/whip//unnamed_geom_15" class="panda/whip/cylinder"/>
                                          <geom name="panda/whip//unnamed_geom_16" class="panda/whip/sphere"/>
                                          <body name="panda/whip/N08" pos="0 0 0.035999999999999997">
                                            <joint name="panda/whip//unnamed_joint_16" class="panda/whip/X"/>
                                            <joint name="panda/whip//unnamed_joint_17" class="panda/whip/Y"/>
                                            <geom name="panda/whip//unnamed_geom_17" class="panda/whip/cylinder"/>
                                            <geom name="panda/whip//unnamed_geom_18" class="panda/whip/sphere"/>
                                            <body name="panda/whip/N09" pos="0 0 0.035999999999999997">
                                              <joint name="panda/whip//unnamed_joint_18" class="panda/whip/X"/>
                                              <joint name="panda/whip//unnamed_joint_19" class="panda/whip/Y"/>
                                              <geom name="panda/whip//unnamed_geom_19" class="panda/whip/cylinder"/>
                                              <geom name="panda/whip//unnamed_geom_20" class="panda/whip/sphere"/>
                                              <body name="panda/whip/N10" pos="0 0 0.035999999999999997">
                                                <joint name="panda/whip//unnamed_joint_20" class="panda/whip/X"/>
                                                <joint name="panda/whip//unnamed_joint_21" class="panda/whip/Y"/>
                                                <geom name="panda/whip//unnamed_geom_21" class="panda/whip/cylinder"/>
                                                <geom name="panda/whip//unnamed_geom_22" class="panda/whip/sphere"/>
                                                <body name="panda/whip/N11" pos="0 0 0.035999999999999997">
                                                  <joint name="panda/whip//unnamed_joint_22" class="panda/whip/X"/>
                                                  <joint name="panda/whip//unnamed_joint_23" class="panda/whip/Y"/>
                                                  <geom name="panda/whip//unnamed_geom_23" class="panda/whip/cylinder"/>
                                                  <geom name="panda/whip//unnamed_geom_24" class="panda/whip/sphere"/>
                                                  <body name="panda/whip/N12" pos="0 0 0.035999999999999997">
                                                    <joint name="panda/whip//unnamed_joint_24" class="panda/whip/X"/>
                                                    <joint name="panda/whip//unnamed_joint_25" class="panda/whip/Y"/>
                                                    <geom name="panda/whip//unnamed_geom_25" class="panda/whip/cylinder"/>
                                                    <geom name="panda/whip//unnamed_geom_26" class="panda/whip/sphere"/>
                                                    <body name="panda/whip/N13" pos="0 0 0.035999999999999997">
                                                      <joint name="panda/whip//unnamed_joint_26" class="panda/whip/X"/>
                                                      <joint name="panda/whip//unnamed_joint_27" class="panda/whip/Y"/>
                                                      <geom name="panda/whip//unnamed_geom_27" class="panda/whip/cylinder"/>
                                                      <geom name="panda/whip//unnamed_geom_28" class="panda/whip/sphere"/>
                                                      <body name="panda/whip/N14" pos="0 0 0.035999999999999997">
                                                        <joint name="panda/whip//unnamed_joint_28" class="panda/whip/X"/>
                                                        <joint name="panda/whip//unnamed_joint_29" class="panda/whip/Y"/>
                                                        <geom name="panda/whip//unnamed_geom_29" class="panda/whip/cylinder"/>
                                                        <geom name="panda/whip//unnamed_geom_30" class="panda/whip/sphere"/>
                                                        <body name="panda/whip/N15" pos="0 0 0.035999999999999997">
                                                          <joint name="panda/whip//unnamed_joint_30" class="panda/whip/X"/>
                                                          <joint name="panda/whip//unnamed_joint_31" class="panda/whip/Y"/>
                                                          <geom name="panda/whip//unnamed_geom_31" class="panda/whip/cylinder"/>
                                                          <geom name="panda/whip//unnamed_geom_32" class="panda/whip/sphere"/>
                                                          <body name="panda/whip/N16" pos="0 0 0.035999999999999997">
                                                            <joint name="panda/whip//unnamed_joint_32" class="panda/whip/X"/>
                                                            <joint name="panda/whip//unnamed_joint_33" class="panda/whip/Y"/>
                                                            <geom name="panda/whip//unnamed_geom_33" class="panda/whip/cylinder"/>
                                                            <geom name="panda/whip//unnamed_geom_34" class="panda/whip/sphere"/>
                                                            <body name="panda/whip/N17" pos="0 0 0.035999999999999997">
                                                            <joint name="panda/whip//unnamed_joint_34" class="panda/whip/X"/>
                                                            <joint name="panda/whip//unnamed_joint_35" class="panda/whip/Y"/>
                                                            <geom name="panda/whip//unnamed_geom_35" class="panda/whip/cylinder"/>
                                                            <geom name="panda/whip//unnamed_geom_36" class="panda/whip/sphere"/>
                                                            <body name="panda/whip/N18" pos="0 0 0.035999999999999997">
                                                            <joint name="panda/whip//unnamed_joint_36" class="panda/whip/X"/>
                                                            <joint name="panda/whip//unnamed_joint_37" class="panda/whip/Y"/>
                                                            <geom name="panda/whip//unnamed_geom_37" class="panda/whip/cylinder"/>
                                                            <geom name="panda/whip//unnamed_geom_38" class="panda/whip/sphere"/>
                                                            <body name="panda/whip/N19" pos="0 0 0.035999999999999997">
                                                            <joint name="panda/whip//unnamed_joint_38" class="panda/whip/X"/>
                                                            <joint name="panda/whip//unnamed_joint_39" class="panda/whip/Y"/>
                                                            <geom name="panda/whip//unnamed_geom_39" class="panda/whip/cylinder"/>
                                                            <geom name="panda/whip//unnamed_geom_40" class="panda/whip/sphere"/>
                                                            <body name="panda/whip/N20" pos="0 0 0.035999999999999997">
                                                            <joint name="panda/whip//unnamed_joint_40" class="panda/whip/X"/>
                                                            <joint name="panda/whip//unnamed_joint_41" class="panda/whip/Y"/>
                                                            <geom name="panda/whip//unnamed_geom_41" class="panda/whip/cylinder"/>
                                                            <geom name="panda/whip//unnamed_geom_42" class="panda/whip/sphere"/>
                                                            <body name="panda/whip/N21" pos="0 0 0.035999999999999997">
                                                            <joint name="panda/whip//unnamed_joint_42" class="panda/whip/X"/>
                                                            <joint name="panda/whip//unnamed_joint_43" class="panda/whip/Y"/>
                                                            <geom name="panda/whip//unnamed_geom_43" class="panda/whip/cylinder"/>
                                                            <geom name="panda/whip//unnamed_geom_44" class="panda/whip/sphere"/>
                                                            <body name="panda/whip/N22" pos="0 0 0.035999999999999997">
                                                            <joint name="panda/whip//unnamed_joint_44" class="panda/whip/X"/>
                                                            <joint name="panda/whip//unnamed_joint_45" class="panda/whip/Y"/>
                                                            <geom name="panda/whip//unnamed_geom_45" class="panda/whip/cylinder"/>
                                                            <geom name="panda/whip//unnamed_geom_46" class="panda/whip/sphere"/>
                                                            <body name="panda/whip/N23" pos="0 0 0.035999999999999997">
                                                            <joint name="panda/whip//unnamed_joint_46" class="panda/whip/X"/>
                                                            <joint name="panda/whip//unnamed_joint_47" class="panda/whip/Y"/>
                                                            <geom name="panda/whip//unnamed_geom_47" class="panda/whip/cylinder"/>
                                                            <geom name="panda/whip//unnamed_geom_48" class="panda/whip/sphere"/>
                                                            <body name="panda/whip/N24" pos="0 0 0.035999999999999997">
                                                            <joint name="panda/whip//unnamed_joint_48" class="panda/whip/X"/>
                                                            <joint name="panda/whip//unnamed_joint_49" class="panda/whip/Y"/>
                                                            <geom name="panda/whip//unnamed_geom_49" class="panda/whip/cylinder"/>
                                                            <geom name="panda/whip//unnamed_geom_50" class="panda/whip/sphere"/>
                                                            <body name="panda/whip/N25" pos="0 0 0.035999999999999997">
                                                            <joint name="panda/whip//unnamed_joint_50" class="panda/whip/X"/>
                                                            <joint name="panda/whip//unnamed_joint_51" class="panda/whip/Y"/>
                                                            <geom name="panda/whip//unnamed_geom_51" class="panda/whip/cylinder"/>
                                                            <geom name="panda/whip//unnamed_geom_52" class="panda/whip/sphere"/>
                                                            <body name="panda/whip/N26" pos="0 0 0.035999999999999997">
                                                            <joint name="panda/whip//unnamed_joint_52" class="panda/whip/X"/>
                                                            <joint name="panda/whip//unnamed_joint_53" class="panda/whip/Y"/>
                                                            <geom name="panda/whip//unnamed_geom_53" class="panda/whip/cylinder"/>
                                                            <geom name="panda/whip//unnamed_geom_54" class="panda/whip/sphere"/>
                                                            <site name="panda/whip/whip_end" pos="0 0 0.035999999999999997"/>
                                                            </body>
                                                            </body>
                                                            </body>
                                                            </body>
                                                            </body>
                                                            </body>
                                                            </body>
                                                            </body>
                                                            </body>
                                                            </body>
                                                          </body>
                                                        </body>
                                                      </body>
                                                    </body>
                                                  </body>
                                                </body>
                                              </body>
                                            </body>
                                          </body>
                                        </body>
                                      </body>
                                    </body>
                                  </body>
                                </body>
                              </body>
                            </body>
                          </body>
                        </body>
                      </body>
                    </body>
                  </body>
                </body>
              </body>
            </body>
          </body>
        </body>
      </body>
    </body>
    <body name="obj/">
      <body name="obj/obj">
        <joint name="obj/obj_jnt" class="obj/" type="ball"/>
        <geom name="obj//unnamed_geom_0" class="obj/visual" material="obj/material_0.007" mesh="obj/07"/>
        <geom name="obj//unnamed_geom_1" class="obj/collision" mass="0.5" mesh="obj/07"/>
      </body>
    </body>
  </worldbody>
  <actuator>
    <motor name="panda/actuator_1" class="panda/panda" ctrlrange="-87 87" forcerange="-87 87" joint="panda/joint1"/>
    <motor name="panda/actuator_2" class="panda/panda" ctrlrange="-87 87" forcerange="-87 87" joint="panda/joint2"/>
    <motor name="panda/actuator_3" class="panda/panda" ctrlrange="-87 87" forcerange="-87 87" joint="panda/joint3"/>
    <motor name="panda/actuator_4" class="panda/panda" ctrlrange="-87 87" forcerange="-87 87" joint="panda/joint4"/>
    <motor name="panda/actuator_5" class="panda/panda" ctrlrange="-12 12" forcerange="-12 12" joint="panda/joint5"/>
    <motor name="panda/actuator_6" class="panda/panda" ctrlrange="-12 12" forcerange="-12 12" joint="panda/joint6"/>
    <motor name="panda/actuator_7" class="panda/panda" ctrlrange="-12 12" forcerange="-12 12" joint="panda/joint7"/>
  </actuator>
</mujoco>
