<mujoco model="panda">
  <compiler angle="radian" autolimits="true"/>

  <option integrator="implicit" impratio="10"/> <!-- 椭圆摩擦锥的摩擦-法向约束阻抗比率, 大于1的设置会使摩擦力比法向力“更硬”, 从而防止滑动, 但不会增加实际摩擦系数.  -->

  <default>
    <default class="panda">
      <material specular="0.5" shininess="0.25"/>
      <joint armature="0.1" damping="1" axis="0 0 1" range="-2.8973 2.8973"/>
      <general dyntype="none" biastype="affine" ctrlrange="-2.8973 2.8973" forcerange="-87 87"/>
      <default class="finger">
        <joint axis="0 1 0" type="slide" range="0 0.04"/>
      </default>

      <default class="visual">
        <geom type="mesh" contype="0" conaffinity="0" group="2"/> <!-- 不检查mesh物体的碰撞 -->
      </default>
      <default class="collision">
        <geom type="mesh" group="3"/>
      </default>
      <site size="0.001" rgba="0.5 0.5 0.5 0.3" group="4"/>
    </default>

    <default class="whip">
      <default class="pandaX">
        <joint type="hinge" axis="1 0 0" pos="0 0 0" springref="0" stiffness="0.242" damping="0.092" /> 
      </default>
      <default class="pandaY">
        <joint type="hinge" axis="0 1 0" pos="0 0 0" springref="0" stiffness="0.242" damping="0.092" /> 
      </default>
      <default class="pandasphere">
        <geom type="sphere" material="white" pos="0 0 0.036" size="0.006" mass="0.012" />
      </default>
      <default class="pandacylinder">
        <geom type="cylinder" material="off_white" fromto="0 0 0 0 0 0.036" size="0.006" mass="0" />
      </default>
    </default>    
  </default>

  <asset>
    <material class="panda" name="white" rgba="1 1 1 1"/>
    <material class="panda" name="off_white" rgba="0.901961 0.921569 0.929412 1"/>
    <material class="panda" name="dark_grey" rgba="0.25 0.25 0.25 1"/>
    <material class="panda" name="green" rgba="0 1 0 1"/>
    <material class="panda" name="light_blue" rgba="0.039216 0.541176 0.780392 1"/>

    <!-- Collision meshes -->
    <mesh name="link0_c" file="assets/link0.stl"/>
    <mesh name="link1_c" file="assets/link1.stl"/>
    <mesh name="link2_c" file="assets/link2.stl"/>
    <mesh name="link3_c" file="assets/link3.stl"/>
    <mesh name="link4_c" file="assets/link4.stl"/>
    <mesh name="link5_c0" file="assets/link5_collision_0.obj"/>
    <mesh name="link5_c1" file="assets/link5_collision_1.obj"/>
    <mesh name="link5_c2" file="assets/link5_collision_2.obj"/>
    <mesh name="link6_c" file="assets/link6.stl"/>
    <mesh name="link7_c" file="assets/link7.stl"/>

    <!-- Visual meshes -->
    <mesh file="assets/link0_0.obj"/>
    <mesh file="assets/link0_1.obj"/>
    <mesh file="assets/link0_2.obj"/>
    <mesh file="assets/link0_3.obj"/>
    <mesh file="assets/link0_4.obj"/>
    <mesh file="assets/link0_5.obj"/>
    <mesh file="assets/link0_7.obj"/>
    <mesh file="assets/link0_8.obj"/>
    <mesh file="assets/link0_9.obj"/>
    <mesh file="assets/link0_10.obj"/>
    <mesh file="assets/link0_11.obj"/>
    <mesh file="assets/link1.obj"/>
    <mesh file="assets/link2.obj"/>
    <mesh file="assets/link3_0.obj"/>
    <mesh file="assets/link3_1.obj"/>
    <mesh file="assets/link3_2.obj"/>
    <mesh file="assets/link3_3.obj"/>
    <mesh file="assets/link4_0.obj"/>
    <mesh file="assets/link4_1.obj"/>
    <mesh file="assets/link4_2.obj"/>
    <mesh file="assets/link4_3.obj"/>
    <mesh file="assets/link5_0.obj"/>
    <mesh file="assets/link5_1.obj"/>
    <mesh file="assets/link5_2.obj"/>
    <mesh file="assets/link6_0.obj"/>
    <mesh file="assets/link6_1.obj"/>
    <mesh file="assets/link6_2.obj"/>
    <mesh file="assets/link6_3.obj"/>
    <mesh file="assets/link6_4.obj"/>
    <mesh file="assets/link6_5.obj"/>
    <mesh file="assets/link6_6.obj"/>
    <mesh file="assets/link6_7.obj"/>
    <mesh file="assets/link6_8.obj"/>
    <mesh file="assets/link6_9.obj"/>
    <mesh file="assets/link6_10.obj"/>
    <mesh file="assets/link6_11.obj"/>
    <mesh file="assets/link6_12.obj"/>
    <mesh file="assets/link6_13.obj"/>
    <mesh file="assets/link6_14.obj"/>
    <mesh file="assets/link6_15.obj"/>
    <mesh file="assets/link6_16.obj"/>
    <mesh file="assets/link7_0.obj"/>
    <mesh file="assets/link7_1.obj"/>
    <mesh file="assets/link7_2.obj"/>
    <mesh file="assets/link7_3.obj"/>
    <mesh file="assets/link7_4.obj"/>
    <mesh file="assets/link7_5.obj"/>
    <mesh file="assets/link7_6.obj"/>
    <mesh file="assets/link7_7.obj"/>
  </asset>

  <worldbody>
    <light name="top" pos="0 0 2" mode="trackcom"/>
    <body name="link0" childclass="panda">
      <inertial mass="0.629769" pos="-0.041018 -0.00014 0.049974"
          fullinertia="0.00315 0.00388 0.004285 8.2904e-7 0.00015 8.2299e-6"/>
      <geom mesh="link0_0" material="off_white" class="visual"/>
      <geom mesh="link0_1" material="dark_grey" class="visual"/>
      <geom mesh="link0_2" material="off_white" class="visual"/>
      <geom mesh="link0_3" material="dark_grey" class="visual"/>
      <geom mesh="link0_4" material="off_white" class="visual"/>
      <geom mesh="link0_5" material="dark_grey" class="visual"/>
      <geom mesh="link0_7" material="white" class="visual"/>
      <geom mesh="link0_8" material="white" class="visual"/>
      <geom mesh="link0_9" material="dark_grey" class="visual"/>
      <geom mesh="link0_10" material="off_white" class="visual"/>
      <geom mesh="link0_11" material="white" class="visual"/>
      <geom mesh="link0_c" class="collision"/>
      <body name="link1" pos="0 0 0.333">
        <inertial mass="4.970684" pos="0.003875 0.002081 -0.04762"
            fullinertia="0.70337 0.70661 0.0091170 -0.00013900 0.0067720 0.019169"/>
        <joint name="joint1"/>
        <geom material="white" mesh="link1" class="visual"/>
        <geom mesh="link1_c" class="collision"/>
        <body name="link2" quat="1 -1 0 0">
          <inertial mass="0.646926" pos="-0.003141 -0.02872 0.003495"
              fullinertia="0.0079620 2.8110e-2 2.5995e-2 -3.925e-3 1.0254e-2 7.04e-4"/>
          <joint name="joint2" range="-1.7628 1.7628"/>
          <geom material="white" mesh="link2" class="visual"/>
          <geom mesh="link2_c" class="collision"/>
          <body name="link3" pos="0 -0.316 0" quat="1 1 0 0">
            <joint name="joint3"/>
            <inertial mass="3.228604" pos="2.7518e-2 3.9252e-2 -6.6502e-2"
                fullinertia="3.7242e-2 3.6155e-2 1.083e-2 -4.761e-3 -1.1396e-2 -1.2805e-2"/>
            <geom mesh="link3_0" material="white" class="visual"/>
            <geom mesh="link3_1" material="white" class="visual"/>
            <geom mesh="link3_2" material="white" class="visual"/>
            <geom mesh="link3_3" material="dark_grey" class="visual"/>
            <geom mesh="link3_c" class="collision"/>
            <body name="link4" pos="0.0825 0 0" quat="1 1 0 0">
              <inertial mass="3.587895" pos="-5.317e-2 1.04419e-1 2.7454e-2"
                  fullinertia="2.5853e-2 1.9552e-2 2.8323e-2 7.796e-3 -1.332e-3 8.641e-3"/>
              <joint name="joint4" range="-3.0718 -0.0698"/>
              <geom mesh="link4_0" material="white" class="visual"/>
              <geom mesh="link4_1" material="white" class="visual"/>
              <geom mesh="link4_2" material="dark_grey" class="visual"/>
              <geom mesh="link4_3" material="white" class="visual"/>
              <geom mesh="link4_c" class="collision"/>
              <body name="link5" pos="-0.0825 0.384 0" quat="1 -1 0 0">
                <inertial mass="1.225946" pos="-1.1953e-2 4.1065e-2 -3.8437e-2"
                    fullinertia="3.5549e-2 2.9474e-2 8.627e-3 -2.117e-3 -4.037e-3 2.29e-4"/>
                <joint name="joint5"/>
                <geom mesh="link5_0" material="dark_grey" class="visual"/>
                <geom mesh="link5_1" material="white" class="visual"/>
                <geom mesh="link5_2" material="white" class="visual"/>
                <geom mesh="link5_c0" class="collision"/>
                <geom mesh="link5_c1" class="collision"/>
                <geom mesh="link5_c2" class="collision"/>
                <body name="link6" quat="1 1 0 0">
                  <inertial mass="1.666555" pos="6.0149e-2 -1.4117e-2 -1.0517e-2"
                      fullinertia="1.964e-3 4.354e-3 5.433e-3 1.09e-4 -1.158e-3 3.41e-4"/>
                  <joint name="joint6" range="-0.0175 3.7525"/>
                  <geom mesh="link6_0" material="off_white" class="visual"/>
                  <geom mesh="link6_1" material="white" class="visual"/>
                  <geom mesh="link6_2" material="dark_grey" class="visual"/>
                  <geom mesh="link6_3" material="white" class="visual"/>
                  <geom mesh="link6_4" material="white" class="visual"/>
                  <geom mesh="link6_5" material="white" class="visual"/>
                  <geom mesh="link6_6" material="white" class="visual"/>
                  <geom mesh="link6_7" material="light_blue" class="visual"/>
                  <geom mesh="link6_8" material="light_blue" class="visual"/>
                  <geom mesh="link6_9" material="dark_grey" class="visual"/>
                  <geom mesh="link6_10" material="dark_grey" class="visual"/>
                  <geom mesh="link6_11" material="white" class="visual"/>
                  <geom mesh="link6_12" material="green" class="visual"/>
                  <geom mesh="link6_13" material="white" class="visual"/>
                  <geom mesh="link6_14" material="dark_grey" class="visual"/>
                  <geom mesh="link6_15" material="dark_grey" class="visual"/>
                  <geom mesh="link6_16" material="white" class="visual"/>
                  <geom mesh="link6_c" class="collision"/>
                  <body name="link7" pos="0.088 0 0" quat="1 1 0 0">
                    <inertial mass="7.35522e-01" pos="1.0517e-2 -4.252e-3 6.1597e-2"
                        fullinertia="1.2516e-2 1.0027e-2 4.815e-3 -4.28e-4 -1.196e-3 -7.41e-4"/>
                    <joint name="joint7"/>
                    <geom mesh="link7_0" material="white" class="visual"/>
                    <geom mesh="link7_1" material="dark_grey" class="visual"/>
                    <geom mesh="link7_2" material="dark_grey" class="visual"/>
                    <geom mesh="link7_3" material="dark_grey" class="visual"/>
                    <geom mesh="link7_4" material="dark_grey" class="visual"/>
                    <geom mesh="link7_5" material="dark_grey" class="visual"/>
                    <geom mesh="link7_6" material="dark_grey" class="visual"/>
                    <geom mesh="link7_7" material="white" class="visual"/>
                    <geom mesh="link7_c" class="collision"/>
                    <body name="whip" childclass="whip" pos="0 0 0.107">
                      <geom name="whip_start" type="sphere" size="0.045" material="white"/>
                      <body name="N00" pos="0 0 0.045">
                        <joint class="pandaX"/>
                        <joint class="pandaY"/>
                        <geom  class="pandacylinder" />
                        <geom  class="pandasphere"/>
                        <body name="N01" pos="0 0 0.036">
                          <joint class="pandaX"/>
                          <joint class="pandaY"/>
                          <geom  class="pandacylinder" />
                          <geom  class="pandasphere"/>
                          <body name="N02" pos="0 0 0.036">
                            <joint class="pandaX"/>
                            <joint class="pandaY"/>
                            <geom  class="pandacylinder" />
                            <geom  class="pandasphere"/>
                            <body name="N03" pos="0 0 0.036">
                              <joint class="pandaX"/>
                              <joint class="pandaY"/>
                              <geom  class="pandacylinder" />
                              <geom  class="pandasphere"/>
                              <body name="N04" pos="0 0 0.036">
                                <joint class="pandaX"/>
                                <joint class="pandaY"/>
                                <geom  class="pandacylinder" />
                                <geom  class="pandasphere"/>
                                <body name="N05" pos="0 0 0.036">
                                  <joint class="pandaX"/>
                                  <joint class="pandaY"/>
                                  <geom  class="pandacylinder" />
                                  <geom  class="pandasphere"/>
                                  <body name="N06" pos="0 0 0.036">
                                    <joint class="pandaX"/>
                                    <joint class="pandaY"/>
                                    <geom  class="pandacylinder" />
                                    <geom  class="pandasphere"/>
                                    <body name="N07" pos="0 0 0.036">
                                      <joint class="pandaX"/>
                                      <joint class="pandaY"/>
                                      <geom  class="pandacylinder" />
                                      <geom  class="pandasphere"/>
                                      <body name="N08" pos="0 0 0.036">
                                        <joint class="pandaX"/>
                                        <joint class="pandaY"/>
                                        <geom  class="pandacylinder" />
                                        <geom  class="pandasphere"/>
                                        <body name="N09" pos="0 0 0.036">
                                          <joint class="pandaX"/>
                                          <joint class="pandaY"/>
                                          <geom  class="pandacylinder" />
                                          <geom  class="pandasphere"/>
                                          <body name="N10" pos="0 0 0.036">
                                            <joint class="pandaX"/>
                                            <joint class="pandaY"/>
                                            <geom  class="pandacylinder" />
                                            <geom  class="pandasphere"/>
                                            <body name="N11" pos="0 0 0.036">
                                              <joint class="pandaX"/>
                                              <joint class="pandaY"/>
                                              <geom  class="pandacylinder" />
                                              <geom  class="pandasphere"/>
                                              <body name="N12" pos="0 0 0.036">
                                                <joint class="pandaX"/>
                                                <joint class="pandaY"/>
                                                <geom  class="pandacylinder" />
                                                <geom  class="pandasphere"/>
                                                <body name="N13" pos="0 0 0.036">
                                                  <joint class="pandaX"/>
                                                  <joint class="pandaY"/>
                                                  <geom  class="pandacylinder" />
                                                  <geom  class="pandasphere"/>
                                                  <body name="N14" pos="0 0 0.036">
                                                    <joint class="pandaX"/>
                                                    <joint class="pandaY"/>
                                                    <geom  class="pandacylinder" />
                                                    <geom  class="pandasphere"/>
                                                    <body name="N15" pos="0 0 0.036">
                                                      <joint class="pandaX"/>
                                                      <joint class="pandaY"/>
                                                      <geom  class="pandacylinder" />
                                                      <geom  class="pandasphere"/>
                                                      <body name="N16" pos="0 0 0.036">
                                                        <joint class="pandaX"/>
                                                        <joint class="pandaY"/>
                                                        <geom  class="pandacylinder" />
                                                        <geom  class="pandasphere"/>
                                                        <body name="N17" pos="0 0 0.036">
                                                          <joint class="pandaX"/>
                                                          <joint class="pandaY"/>
                                                          <geom  class="pandacylinder" />
                                                          <geom  class="pandasphere"/>
                                                          <body name="N18" pos="0 0 0.036">
                                                            <joint class="pandaX"/>
                                                            <joint class="pandaY"/>
                                                            <geom  class="pandacylinder" />
                                                            <geom  class="pandasphere"/>
                                                            <body name="N19" pos="0 0 0.036">
                                                              <joint class="pandaX"/>
                                                              <joint class="pandaY"/>
                                                              <geom  class="pandacylinder" />
                                                              <geom  class="pandasphere"/>
                                                              <body name="N20" pos="0 0 0.036">
                                                                <joint class="pandaX"/>
                                                                <joint class="pandaY"/>
                                                                <geom  class="pandacylinder" />
                                                                <geom  class="pandasphere"/>
                                                                <body name="N21" pos="0 0 0.036">
                                                                  <joint class="pandaX"/>
                                                                  <joint class="pandaY"/>
                                                                  <geom  class="pandacylinder" />
                                                                  <geom  class="pandasphere"/>
                                                                  <body name="N22" pos="0 0 0.036">
                                                                    <joint class="pandaX"/>
                                                                    <joint class="pandaY"/>
                                                                    <geom  class="pandacylinder" />
                                                                    <geom  class="pandasphere"/>
                                                                    <body name="N23" pos="0 0 0.036">
                                                                      <joint class="pandaX"/>
                                                                      <joint class="pandaY"/>
                                                                      <geom  class="pandacylinder" />
                                                                      <geom  class="pandasphere"/>
                                                                      <body name="N24" pos="0 0 0.036">
                                                                        <joint class="pandaX"/>
                                                                        <joint class="pandaY"/>
                                                                        <geom  class="pandacylinder" />
                                                                        <geom  class="pandasphere"/>
                                                                        <body name="N25" pos="0 0 0.036">
                                                                          <joint class="pandaX"/>
                                                                          <joint class="pandaY"/>
                                                                          <geom  class="pandacylinder" />
                                                                          <geom  class="pandasphere"/>                       
                                                                          <body name="N26" pos="0 0 0.036">
                                                                            <joint class="pandaX"/>
                                                                            <joint class="pandaY"/>
                                                                            <geom  class="pandacylinder" />
                                                                            <geom  class="pandasphere"/>
                                                                            <site name="whip_end" pos="0 0 0.036"/> 
                                                                          </body>
                                                                        </body>
                                                                      </body>
                                                                    </body>
                                                                  </body>
                                                                </body>
                                                              </body>
                                                            </body>
                                                          </body>
                                                        </body>
                                                      </body>
                                                    </body>
                                                  </body>
                                                </body>
                                              </body>
                                            </body>
                                          </body>
                                        </body>
                                      </body>
                                    </body>
                                  </body>
                                </body>
                              </body>
                            </body>
                          </body>
                        </body>
                      </body>
                    </body>
                  </body>
                </body>
              </body>
            </body>
          </body>
        </body>
      </body>
    </body>
  </worldbody>

  <actuator>
    <!-- 作用在joint上的forcerange指的是力矩 -->
    <general class="panda" name="actuator1" joint="joint1" gainprm="4500" biasprm="0 -4500 -450"/>
    <general class="panda" name="actuator2" joint="joint2" gainprm="4500" biasprm="0 -4500 -450" ctrlrange="-1.7628 1.7628"/>
    <general class="panda" name="actuator3" joint="joint3" gainprm="3500" biasprm="0 -3500 -350"/>
    <general class="panda" name="actuator4" joint="joint4" gainprm="3500" biasprm="0 -3500 -350" ctrlrange="-3.0718 -0.0698"/>
    <general class="panda" name="actuator5" joint="joint5" gainprm="2000" biasprm="0 -2000 -200" forcerange="-12 12"/>
    <general class="panda" name="actuator6" joint="joint6" gainprm="2000" biasprm="0 -2000 -200" forcerange="-12 12" ctrlrange="-0.0175 3.7525"/>
    <general class="panda" name="actuator7" joint="joint7" gainprm="2000" biasprm="0 -2000 -200" forcerange="-12 12"/>
  </actuator>

  <!-- <keyframe>
    <key name="home" qpos="0 0 0 -1.57079 0 1.57079 -0.7853"
        ctrl="0 0 0 -1.57079 0 1.57079 -0.7853"/>
  </keyframe> -->
</mujoco>
